Workbook

Sheet QUESTIONARI
B1: QÜESTIONARI AVALUACIÓ ASSISTENTS
F2: Valors enquesta
B3: La teva opinió sobre el curs que acabes de realitzar és un element clau per poder millorar la nostra oferta formativa. | F3: 1 - Gens d'acord 2 - Poc d'acord 3 - Bastant d'acord 4 - Molt d'acord
B4: T'agrairem que dediquis uns minuts a contestar amb cura aquest qüestionari.
B5: Moltes gràcies per les vostres aportacions.
B7: 1.- Dades identificatives
B8: Acció formativa:
B9: Cognoms i nom del formador:
B10: Lloc d'impartició:
B11: Codi acció:
B13: 2.- Motius d'assistència
B14: Per què vas escollir fer aquest curs? | D14: Quina era la teva motivació principal?
B15: Marca amb una X: | D15: Marca amb una X:
B16: Per iniciativa pròpia | D16: Fer millor la meva feina en el lloc de treball actual
B17: Per indicació del meu cap | D17: Preparar-me per a una feina que vull fer en el futur
B18: Per recomanació d'un company | D18: Altres
B19: Altres
B21: 3.- Opinió en relació al programa
C22: 1 | D22: 2 | E22: 3 | F22: 4
B23: El contingut desenvolupat permet assolir els objectius previstos.
B24: Està ben estructurat.
B25: S'adapta a la realitat de l'Administració local.
B27: 4.- Opinió en relació a la metodologia
C28: 1 | D28: 2 | E28: 3 | F28: 4
B29: Les sessions han estat interessants i amenes.
B30: Els conceptes s'han treballat de forma pràctica i activa per tal de facilitar-ne l'aprenentatge.
B31: La documentació lliurada és adequada i de qualitat.
B33: 5.- Opinió sobre el docent
C34: 1 | D34: 2 | E34: 3 | F34: 4
B35: Ha mostrat un bon domini de la matèria.
B36: Ha estat clar en les seves explicacions.
B37: S'ha mostrat receptiu davant les preguntes i comentaris dels participants.
B38: Ha contribuït a crear i mantenir un bon ambient a l'aula.
B40: 6.- Opinió sobre els participants
C41: 1 | D41: 2 | E41: 3 | F41: 4
B42: El grup era suficientment homogeni com perquè tots hagin pogut seguir el ritme de les sessions.
B43: El grup ha mostrat una actitud participativa i constructiva.
B45: 7.- Opinió sobre l'entorn
C46: 1 | D46: 2 | E46: 3 | F46: 4
B47: És fàcil accedir a les instal·lacions.
...

Sheet EXPORT
A1: CodigoAccion | B1: AccioFormativa | C1: Formador | D1: LlocImparticio | E1: ValoracioGlobal_1_10 | F1: Motius_Escollir | G1: Motivacio_Principal | H1: Recomana | I1: Motius_Recomana | J1: PuntsForts | K1: PuntsFebles | L1: Aplicacio | M1: AltresComentaris | N1: Q01 | O1: Q02 | P1: Q03 | Q1: Q04 | R1: Q05 | S1: Q06 | T1: Q07 | U1: Q08 | V1: Q09 | W1: Q10 | X1: Q11 | Y1: Q12 | Z1: Q13 | AA1: Q14 | AB1: Q15 | AC1: Q16 | AD1: Q17 | AE1: Q18 | AF1: Q19 | AG1: Q20 | AH1: Asistent
A2: =QUESTIONARI!C11 -> 0 | B2: =QUESTIONARI!C8 -> 0 | C2: =QUESTIONARI!C9 -> 0 | D2: =QUESTIONARI!C10 -> 0 | E2: =QUESTIONARI!C64 -> 0 | F2: =IF(QUESTIONARI!C16="X","Per iniciativa pròpia; ","") & IF(QUESTIONARI!C17="X","Per indicació del meu cap; ","") & IF(QUESTIONARI!C18="X","Per recomanació d'un company; ","") & IF(QUESTIONARI!C19="X","Altres (especificar)","") | G2: =IF(QUESTIONARI!G16="X","Fer millor la meva feina en el lloc de treball actual; ","") & IF(QUESTIONARI!G17="X","Preparar-me per a una feina que vull fer en el futur; ","") & IF(QUESTIONARI!G18="X","Altres (especificar); ","") & IF(QUESTIONARI!G19="X","","") | H2: =QUESTIONARI!C82 -> 0 | I2: =QUESTIONARI!B84 -> 0 | J2: =QUESTIONARI!B68 -> 0 | K2: =QUESTIONARI!B73 -> 0 | L2: =QUESTIONARI!B78 -> 0 | M2: =QUESTIONARI!B89 -> 0 | N2: =IF(QUESTIONARI!C23="X","Gens d'acord",IF(QUESTIONARI!D23="X","Poc d'acord",IF(QUESTIONARI!E23="X","Bastant d'acord",IF(QUESTIONARI!F23="X","Molt d'acord","")))) | O2: =IF(QUESTIONARI!C24="X","Gens d'acord",IF(QUESTIONARI!D24="X","Poc d'acord",IF(QUESTIONARI!E24="X","Bastant d'acord",IF(QUESTIONARI!F24="X","Molt d'acord","")))) | P2: =IF(QUESTIONARI!C25="X","Gens d'acord",IF(QUESTIONARI!D25="X","Poc d'acord",IF(QUESTIONARI!E25="X","Bastant d'acord",IF(QUESTIONARI!F25="X","Molt d'acord","")))) | Q2: =IF(QUESTIONARI!C29="X","Gens d'acord",IF(QUESTIONARI!D29="X","Poc d'acord",IF(QUESTIONARI!E29="X","Bastant d'acord",IF(QUESTIONARI!F29="X","Molt d'acord","")))) | R2: =IF(QUESTIONARI!C30="X","Gens d'acord",IF(QUESTIONARI!D30="X","Poc d'acord",IF(QUESTIONARI!E30="X","Bastant d'acord",IF(QUESTIONARI!F30="X","Molt d'acord","")))) | S2: =IF(QUESTIONARI!C31="X","Gens d'acord",IF(QUESTIONARI!D31="X","Poc d'acord",IF(QUESTIONARI!E31="X","Bastant d'acord",IF(QUESTIONARI!F31="X","Molt d'acord","")))) | T2: =IF(QUESTIONARI!C35="X","Gens d'acord",IF(QUESTIONARI!D35="X","Poc d'acord",IF(QUESTIONARI!E35="X","Bastant d'acord",IF(QUESTIONARI!F35="X","Molt d'acord","")))) | U2: =IF(QUESTIONARI!C36="X","Gens d'acord",IF(QUESTIONARI!D36="X","Poc d'acord",IF(QUESTIONARI!E36="X","Bastant d'acord",IF(QUESTIONARI!F36="X","Molt d'acord","")))) | V2: =IF(QUESTIONARI!C37="X","Gens d'acord",IF(QUESTIONARI!D37="X","Poc d'acord",IF(QUESTIONARI!E37="X","Bastant d'acord",IF(QUESTIONARI!F37="X","Molt d'acord","")))) | W2: =IF(QUESTIONARI!C38="X","Gens d'acord",IF(QUESTIONARI!D38="X","Poc d'acord",IF(QUESTIONARI!E38="X","Bastant d'acord",IF(QUESTIONARI!F38="X","Molt d'acord","")))) | X2: =IF(QUESTIONARI!C42="X","Gens d'acord",IF(QUESTIONARI!D42="X","Poc d'acord",IF(QUESTIONARI!E42="X","Bastant d'acord",IF(QUESTIONARI!F42="X","Molt d'acord","")))) | Y2: =IF(QUESTIONARI!C43="X","Gens d'acord",IF(QUESTIONARI!D43="X","Poc d'acord",IF(QUESTIONARI!E43="X","Bastant d'acord",IF(QUESTIONARI!F43="X","Molt d'acord","")))) | Z2: =IF(QUESTIONARI!C47="X","Gens d'acord",IF(QUESTIONARI!D47="X","Poc d'acord",IF(QUESTIONARI!E47="X","Bastant d'acord",IF(QUESTIONARI!F47="X","Molt d'acord","")))) | AA2: =IF(QUESTIONARI!C48="X","Gens d'acord",IF(QUESTIONARI!D48="X","Poc d'acord",IF(QUESTIONARI!E48="X","Bastant d'acord",IF(QUESTIONARI!F48="X","Molt d'acord","")))) | AB2: =IF(QUESTIONARI!C49="X","Gens d'acord",IF(QUESTIONARI!D49="X","Poc d'acord",IF(QUESTIONARI!E49="X","Bastant d'acord",IF(QUESTIONARI!F49="X","Molt d'acord","")))) | AC2: =IF(QUESTIONARI!C53="X","Gens d'acord",IF(QUESTIONARI!D53="X","Poc d'acord",IF(QUESTIONARI!E53="X","Bastant d'acord",IF(QUESTIONARI!F53="X","Molt d'acord","")))) | AD2: =IF(QUESTIONARI!C54="X","Gens d'acord",IF(QUESTIONARI!D54="X","Poc d'acord",IF(QUESTIONARI!E54="X","Bastant d'acord",IF(QUESTIONARI!F54="X","Molt d'acord","")))) | AE2: =IF(QUESTIONARI!C55="X","Gens d'acord",IF(QUESTIONARI!D55="X","Poc d'acord",IF(QUESTIONARI!E55="X","Bastant d'acord",IF(QUESTIONARI!F55="X","Molt d'acord","")))) | AF2: =IF(QUESTIONARI!C59="X","Gens d'acord",IF(QUESTIONARI!D59="X","Poc d'acord",IF(QUESTIONARI!E59="X","Bastant d'acord",IF(QUESTIONARI!F59="X","Molt d'acord","")))) | AG2: =IF(QUESTIONARI!C60="X","Gens d'acord",IF(QUESTIONARI!D60="X","Poc d'acord",IF(QUESTIONARI!E60="X","Bastant d'acord",IF(QUESTIONARI!F60="X","Molt d'acord","")))) | AH2: =QUESTIONARI!C12 -> 0
